Workbook
Name SALDOBALANSE_1_10_2008_ALLEKTO: 'Areal - Budsjett 2020'!$A$5:$D$142
Name SALDOBALANSE_1_10_2008_ALLEKTO: 'Areal - Gruppen'!$A$5:$D$86
Name SALDOBALANSE_1_10_2008_ALLEKTO: 'Fritzøe - budsj 2020'!$A$5:$D$157
Name SALDOBALANSE_1_10_2008_ALLEKTO: 'Fritzøe - Budsjett 2019'!$A$5:$D$155
Name SALDOBALANSE_1_10_2008_ALLEKTO: 'Fritzøe - budsjett service'!$A$5:$D$156
Name SALDOBALANSE_1_10_2008_ALLEKTO: 'KONSERN - Budsjett 2019'!$A$5:$D$98

Sheet Areal - Gruppen
A1: RESULTATBUDSJETT - 2020 | C1: AREAL-GRUPPEN AS
A3: Konto | B3: Kontonavn | C3: % | D3: Jan | E3: Feb | F3: Mar | G3: Apr | H3: Mai | I3: Jun | J3: Jul | K3: Aug | L3: Sep | M3: Okt | N3: Nov | O3: Des | P3: Total
A4: INNTEKTER
A5: 3000 | B5: Inntekter viderefakturering lokaler | C5: =P5/$P$14 -> 0.26600325 | D5: =16931+29630+30553*1.014 -> 77541.742 | E5: =D5 -> 77541.742 | F5: =E5 -> 77541.742 | G5: =F5 -> 77541.742 | H5: =G5 -> 77541.742 | I5: =H5 -> 77541.742 | J5: =I5 -> 77541.742 | K5: =J5 -> 77541.742 | L5: =K5 -> 77541.742 | ... O5: =N5 -> 77541.742 | P5: =SUM(D5:O5) -> 930500.9
A6: 3001 | B6: Fakturering regnskapstjenester | C6: =P6/$P$14 -> 0.1372181 | D6: 40000 | E6: =D6 -> 40000 | F6: =E6 -> 40000 | G6: =F6 -> 40000 | H6: =G6 -> 40000 | I6: =H6 -> 40000 | J6: =I6 -> 40000 | K6: =J6 -> 40000 | L6: =K6 -> 40000 | ... O6: =N6 -> 40000 | P6: =SUM(D6:O6) -> 480000
A7: 3002 | B7: Fakturering renhold | C7: =P7/$P$14 -> 0.014459357 | D7: =1365+1500+1350 -> 4215 | E7: =D7 -> 4215 | F7: =E7 -> 4215 | G7: =F7 -> 4215 | H7: =G7 -> 4215 | I7: =H7 -> 4215 | J7: =I7 -> 4215 | K7: =J7 -> 4215 | L7: =K7 -> 4215 | ... O7: =N7 -> 4215 | P7: =SUM(D7:O7) -> 50580
A8: 3003 | B8: Faktuering IT-kostnader | C8: =P8/$P$14 -> 0.014922468 | D8: =450+900+1500+1500 -> 4350 | E8: =D8 -> 4350 | F8: =E8 -> 4350 | G8: =F8 -> 4350 | H8: =G8 -> 4350 | I8: =H8 -> 4350 | J8: =I8 -> 4350 | K8: =J8 -> 4350 | L8: =K8 -> 4350 | ... O8: =N8 -> 4350 | P8: =SUM(D8:O8) -> 52200
A9: 3004 | B9: Fakturering strøm | C9: =P9/$P$14 -> 0.019210533 | D9: =1800+1800+2000 -> 5600 | E9: =D9 -> 5600 | F9: =E9 -> 5600 | G9: =F9 -> 5600 | H9: =G9 -> 5600 | I9: =H9 -> 5600 | J9: =I9 -> 5600 | K9: =J9 -> 5600 | L9: =K9 -> 5600 | ... O9: =N9 -> 5600 | P9: =SUM(D9:O9) -> 67200
A10: 3005 | B10: Fakturering kantinekostnader | C10: =P10/$P$14 -> 0.0082330857 | D10: =6*400 -> 2400 | E10: =D10 -> 2400 | F10: =E10 -> 2400 | G10: =F10 -> 2400 | H10: =G10 -> 2400 | I10: =H10 -> 2400 | J10: =I10 -> 2400 | K10: =J10 -> 2400 | L10: =K10 -> 2400 | ... O10: =N10 -> 2400 | P10: =SUM(D10:O10) -> 28800
A11: 3006 | B11: Fakturering finans (Fritzøe) | C11: =P11/$P$14 -> 0.051456786 | D11: 15000 | E11: =D11 -> 15000 | F11: =E11 -> 15000 | G11: =F11 -> 15000 | H11: =G11 -> 15000 | I11: =H11 -> 15000 | J11: =I11 -> 15000 | K11: =J11 -> 15000 | L11: =K11 -> 15000 | ... O11: =N11 -> 15000 | P11: =SUM(D11:O11) -> 180000
A12: 3020 | B12: Fakturering konsernkostnader | C12: =P12/$P$14 -> 0.41851519 | D12: 122000 | E12: =D12 -> 122000 | F12: =E12 -> 122000 | G12: =F12 -> 122000 | H12: =G12 -> 122000 | I12: =H12 -> 122000 | J12: =I12 -> 122000 | K12: =J12 -> 122000 | L12: =K12 -> 122000 | ... O12: =N12 -> 122000 | P12: =SUM(D12:O12) -> 1464000
A13: 3030 | B13: Fakturering rgnskapstjenester | C13: =P13/$P$14 -> 0.069981229 | D13: =30*680 -> 20400 | E13: =D13 -> 20400 | F13: =E13 -> 20400 | G13: =F13 -> 20400 | H13: =G13 -> 20400 | I13: =H13 -> 20400 | J13: =I13 -> 20400 | K13: =J13 -> 20400 | L13: =K13 -> 20400 | ... O13: =N13 -> 20400 | P13: =SUM(D13:O13) -> 244800
B14: Sum inntekter | C14: =P14/$P$14 -> 1 | D14: =SUM(D5:D13) -> 291506.74 | E14: =SUM(E5:E13) -> 291506.74 | F14: =SUM(F5:F13) -> 291506.74 | G14: =SUM(G5:G13) -> 291506.74 | H14: =SUM(H5:H13) -> 291506.74 | I14: =SUM(I5:I13) -> 291506.74 | J14: =SUM(J5:J13) -> 291506.74 | K14: =SUM(K5:K13) -> 291506.74 | ... P14: =SUM(P5:P13) -> 3498080.9 | IV14: =SUM(D14:IU14) -> 6996161.8
A16: VAREKOSTNADER
A17: 4500 | B17: Strøm (viderefakt) | C17: =P17/$P$14 -> 0.017464121 | D17: =D9/1.1 -> 5090.9091 | E17: =D17 -> 5090.9091 | F17: =E17 -> 5090.9091 | G17: =F17 -> 5090.9091 | H17: =G17 -> 5090.9091 | I17: =H17 -> 5090.9091 | J17: =I17 -> 5090.9091 | K17: =J17 -> 5090.9091 | L17: =K17 -> 5090.9091 | ... O17: =N17 -> 5090.9091 | P17: =SUM(D17:O17) -> 61090.909
A18: 4501 | B18: Husleie (viderefakt) | C18: =P18/$P$14 -> 0.24559295 | D18: 71592 | E18: =D18 -> 71592 | F18: =E18 -> 71592 | G18: =F18 -> 71592 | H18: =G18 -> 71592 | I18: =H18 -> 71592 | J18: =I18 -> 71592 | K18: =J18 -> 71592 | L18: =K18 -> 71592 | ... O18: =N18 -> 71592 | P18: =SUM(D18:O18) -> 859104
A19: 4502 | B19: Renhold (viderefakt) | C19: =P19/$P$14 -> 0.012774319 | D19: =4.33*860 -> 3723.8 | E19: =D19 -> 3723.8 | F19: =E19 -> 3723.8 | G19: =F19 -> 3723.8 | H19: =G19 -> 3723.8 | I19: =H19 -> 3723.8 | J19: =I19 -> 3723.8 | K19: =J19 -> 3723.8 | L19: =K19 -> 3723.8 | ... O19: =N19 -> 3723.8 | P19: =SUM(D19:O19) -> 44685.6
A20: 4503 | B20: IT-kostnader (viderefakt) | C20: =P20/$P$14 -> 0.01372181 | D20: 4000 | E20: =D20 -> 4000 | F20: =E20 -> 4000 | G20: =F20 -> 4000 | H20: =G20 -> 4000 | I20: =H20 -> 4000 | J20: =I20 -> 4000 | K20: =J20 -> 4000 | L20: =K20 -> 4000 | ... O20: =N20 -> 4000 | P20: =SUM(D20:O20) -> 48000
A21: 4504 | B21: Kantinekostnader (viderefakt) | C21: =P21/$P$14 -> 0.01372181 | D21: =4000 -> 4000 | E21: =D21 -> 4000 | F21: =E21 -> 4000 | G21: =F21 -> 4000 | H21: =G21 -> 4000 | I21: =H21 -> 4000 | J21: =I21 -> 4000 | K21: =J21 -> 4000 | L21: =K21 -> 4000 | ... O21: =N21 -> 4000 | P21: =SUM(D21:O21) -> 48000
A22: 4505 | B22: Øvrige felleskostnader (viderefakt) | C22: =P22/$P$14 -> 0.0034304524 | D22: 1000 | E22: =D22 -> 1000 | F22: =E22 -> 1000 | G22: =F22 -> 1000 | H22: =G22 -> 1000 | I22: =H22 -> 1000 | J22: =I22 -> 1000 | K22: =J22 -> 1000 | L22: =K22 -> 1000 | ... O22: =N22 -> 1000 | P22: =SUM(D22:O22) -> 12000
B23: Sum varekostnader | C23: =P23/$P$14 -> 0.30670546 | D23: =SUM(D17:D22) -> 89406.709 | E23: =SUM(E17:E22) -> 89406.709 | F23: =SUM(F17:F22) -> 89406.709 | G23: =SUM(G17:G22) -> 89406.709 | H23: =SUM(H17:H22) -> 89406.709 | I23: =SUM(I17:I22) -> 89406.709 | J23: =SUM(J17:J22) -> 89406.709 | K23: =SUM(K17:K22) -> 89406.709 | ... P23: =SUM(P17:P22) -> 1072880.5 | Q23: =P23/$P$14 -> 0.30670546
A25: DEKNINGSGRAD 1 | C25: =P25/$P$14 -> 0.69329454 | D25: =D14-D23 -> 202100.03 | E25: =E14-E23 -> 202100.03 | F25: =F14-F23 -> 202100.03 | G25: =G14-G23 -> 202100.03 | H25: =H14-H23 -> 202100.03 | I25: =I14-I23 -> 202100.03 | J25: =J14-J23 -> 202100.03 | K25: =K14-K23 -> 202100.03 | ... O25: =O14-O23 -> 202100.03 | P25: =SUM(D25:O25) -> 2425200.4
A27: LØNNSKOSTNADER
A28: 5000 | B28: Lønn til ansatte | C28: =P28/$P$14 -> 0.4090338 | D28: =82500+680000/12-50000 -> 89166.667 | E28: =D28 -> 89166.667 | F28: =82500+680000/12 -> 139166.67 | G28: =F28 -> 139166.67 | H28: =G28 -> 139166.67 | I28: =H28 -> 139166.67 | J28: 0 | K28: =I28 -> 139166.67 | L28: =K28 -> 139166.67 | M28: =L28 -> 139166.67 | N28: =M28 -> 139166.67 | O28: =N28 -> 139166.67 | P28: =SUM(D28:O28) -> 1430833.3
A29: 5001 | B29: Overtid | C29: =P29/$P$14 -> 0 | D29: 0 | E29: 0 | F29: 0 | G29: 0 | H29: 0 | I29: 0 | J29: 0 | K29: 0 | L29: 0 | M29: 0 | N29: 0 | O29: 0 | P29: =SUM(D29:O29) -> 0
A30: 5090 | B30: Feriepenger | C30: =P30/$P$14 -> 0.049084056 | D30: =SUM(D28*12/100) -> 10700 | E30: =SUM(E28*12/100) -> 10700 | F30: =SUM(F28*12/100) -> 16700 | G30: =SUM(G28*12/100) -> 16700 | H30: =SUM(H28*12/100) -> 16700 | I30: =SUM(I28*12/100) -> 16700 | J30: =SUM(J28*12/100) -> 0 | K30: =SUM(K28*12/100) -> 16700 | ... O30: =SUM(O28*12/100) -> 16700 | P30: =SUM(D30:O30) -> 171700
A31: 5110 | B31: Sykepenger | C31: =P31/$P$14 -> 0 | P31: =SUM(D31:O31) -> 0
A32: 5182 | B32: Arbeidsgiveravgift påløpne feriepenger | C32: =P32/$P$14 -> 0.0038776404 | D32: =SUM(D30*7.9%) -> 845.3 | E32: =SUM(E30*7.9%) -> 845.3 | F32: =SUM(F30*7.9%) -> 1319.3 | G32: =SUM(G30*7.9%) -> 1319.3 | H32: =SUM(H30*7.9%) -> 1319.3 | I32: =SUM(I30*7.9%) -> 1319.3 | J32: =SUM(J30*7.9%) -> 0 | K32: =SUM(K30*7.9%) -> 1319.3 | ... O32: =SUM(O30*7.9%) -> 1319.3 | P32: =SUM(D32:O32) -> 13564.3
A33: 5330 | B33: Styrehonorar | C33: =P33/$P$14 -> 0.071467758 | D33: =250000/12 -> 20833.333 | E33: =D33 -> 20833.333 | F33: =E33 -> 20833.333 | G33: =F33 -> 20833.333 | H33: =G33 -> 20833.333 | I33: =H33 -> 20833.333 | J33: =I33 -> 20833.333 | K33: =J33 -> 20833.333 | L33: =K33 -> 20833.333 | ... O33: =N33 -> 20833.333 | P33: =SUM(D33:O33) -> 250000
A34: 5400 | B34: Arbeidsgiveravgift | C34: =P34/$P$14 -> 0.037959623 | D34: =(D28+D33)*7.9% -> 8690 | E34: =(E28+E33)*7.9% -> 8690 | F34: =(F28+F33)*7.9% -> 12640 | G34: =(G28+G33)*7.9% -> 12640 | H34: =(H28+H33)*7.9% -> 12640 | I34: =(I28+I33)*7.9% -> 12640 | J34: =(J28+J33)*7.9% -> 1645.8333 | K34: =(K28+K33)*7.9% -> 12640 | ... O34: =(O28+O33)*7.9% -> 12640 | P34: =SUM(D34:O34) -> 132785.83
B35: Sum lønnskostnader | C35: =P35/$P$14 -> 0.57142288 | D35: =SUM(D28:D34) -> 130235.3 | E35: =SUM(E28:E34) -> 130235.3 | F35: =SUM(F28:F34) -> 190659.3 | G35: =SUM(G28:G34) -> 190659.3 | H35: =SUM(H28:H34) -> 190659.3 | I35: =SUM(I28:I34) -> 190659.3 | J35: =SUM(J28:J34) -> 22479.167 | K35: =SUM(K28:K34) -> 190659.3 | ... P35: =SUM(P28:P34) -> 1998883.5
A37: ANDRE PERSONALKOSTNADER
A38: 5920 | B38: Yrkesskadeforsikring | C38: =P38/$P$14 -> 0.0008576131 | D38: 250 | E38: =D38 -> 250 | F38: =E38 -> 250 | G38: =F38 -> 250 | H38: =G38 -> 250 | I38: =H38 -> 250 | J38: =I38 -> 250 | K38: =J38 -> 250 | L38: =K38 -> 250 | ... O38: =N38 -> 250 | P38: =SUM(D38:O38) -> 3000
A39: 5945 | B39: Innskuddsbasert tjenestepensjon | C39: =P39/$P$14 -> 0.016709162 | D39: =SUM(F28*3.5/100) -> 4870.8333 | E39: =D39 -> 4870.8333 | F39: =E39 -> 4870.8333 | G39: =F39 -> 4870.8333 | H39: =G39 -> 4870.8333 | I39: =H39 -> 4870.8333 | J39: =I39 -> 4870.8333 | K39: =J39 -> 4870.8333 | L39: =K39 -> 4870.8333 | ... O39: =N39 -> 4870.8333 | P39: =SUM(D39:O39) -> 58450
A40: 5950 | B40: Kurskostnader | C40: =P40/$P$14 -> 0.017152262 | D40: 5000 | E40: =D40 -> 5000 | F40: =E40 -> 5000 | G40: =F40 -> 5000 | H40: =G40 -> 5000 | I40: =H40 -> 5000 | J40: =I40 -> 5000 | K40: =J40 -> 5000 | L40: =K40 -> 5000 | ... O40: =N40 -> 5000 | P40: =SUM(D40:O40) -> 60000
A41: 5990 | B41: Andre personalkostnader | C41: =P41/$P$14 -> 0.0034304524 | D41: 1000 | E41: =D41 -> 1000 | F41: =E41 -> 1000 | G41: =F41 -> 1000 | H41: =G41 -> 1000 | I41: =H41 -> 1000 | J41: =I41 -> 1000 | K41: =J41 -> 1000 | L41: =K41 -> 1000 | ... O41: =N41 -> 1000 | P41: =SUM(D41:O41) -> 12000
B42: Sum andre personalkostnader | C42: =P42/$P$14 -> 0.038149489 | D42: =SUM(D38:D41) -> 11120.833 | E42: =SUM(E38:E41) -> 11120.833 | F42: =SUM(F38:F41) -> 11120.833 | G42: =SUM(G38:G41) -> 11120.833 | H42: =SUM(H38:H41) -> 11120.833 | I42: =SUM(I38:I41) -> 11120.833 | J42: =SUM(J38:J41) -> 11120.833 | K42: =SUM(K38:K41) -> 11120.833 | ... P42: =SUM(P38:P41) -> 133450
B44: SUM LØNNS- OG PERSONALKOSTNADER | D44: =D35+D42 -> 141356.13 | E44: =E35+E42 -> 141356.13 | F44: =F35+F42 -> 201780.13 | G44: =G35+G42 -> 201780.13 | H44: =H35+H42 -> 201780.13 | I44: =I35+I42 -> 201780.13 | J44: =J35+J42 -> 33600 | K44: =K35+K42 -> 201780.13 | ... P44: =P35+P42 -> 2132333.5
A46: DEKNINGSGRAD 1 | C46: =P46/$P$14 -> 0.083722171 | D46: =D25-D44 -> 60743.9 | E46: =E25-E44 -> 60743.9 | F46: =F25-F44 -> 319.89958 | G46: =G25-G44 -> 319.89958 | H46: =H25-H44 -> 319.89958 | I46: =I25-I44 -> 319.89958 | J46: =J25-J44 -> 168500.03 | K46: =K25-K44 -> 319.89958 | ... O46: =O25-O44 -> 319.89958 | P46: =SUM(D46:O46) -> 292866.93
A48: KOSTNADSFØRTE ANSKAFFELSER
...

Sheet Areal - Budsjett 2020
A1: RESULTATBUDSJETT - 2020 | C1: AREAL BYGGSERVICE AS
A3: Konto | B3: Kontonavn | C3: % | D3: Jan | E3: Feb | F3: Mar | G3: Apr | H3: Mai | I3: Jun | J3: Jul | K3: Aug | L3: Sep | M3: Okt | N3: Nov | O3: Des | P3: Total
A4: INNTEKTER
A5: 3010 | B5: Inntekter byggearbeid | C5: =P5/$P$8 -> 0.26706745 | D5: ='Areal - forutsetn.'!G48 -> 613348.12 | E5: ='Areal - forutsetn.'!H48 -> 718990.02 | F5: ='Areal - forutsetn.'!I48 -> 753227.64 | G5: ='Areal - forutsetn.'!J48 -> 582039.54 | H5: ='Areal - forutsetn.'!K48 -> 650514.78 | I5: ='Areal - forutsetn.'!L48 -> 650514.78 | J5: ='Areal - forutsetn.'!M48 -> 342376.2 | K5: ='Areal - forutsetn.'!N48 -> 575192.02 | ... O5: ='Areal - forutsetn.'!R48 -> 617989.04 | P5: =SUM(D5:O5) -> 7769010.7
A6: 3011 | B6: Inntekter malerarbeid | C6: =P6/$P$8 -> 0.68343112 | D6: ='Areal - forutsetn.'!G47 -> 1760281.6 | E6: ='Areal - forutsetn.'!H47 -> 1731740.8 | F6: ='Areal - forutsetn.'!I47 -> 1814204.7 | G6: ='Areal - forutsetn.'!J47 -> 1401885.4 | H6: ='Areal - forutsetn.'!K47 -> 1848108.2 | I6: ='Areal - forutsetn.'!L47 -> 1848108.2 | J6: ='Areal - forutsetn.'!M47 -> 972688.5 | K6: ='Areal - forutsetn.'!N47 -> 1634116.7 | ... O6: ='Areal - forutsetn.'!R47 -> 1399395.7 | P6: =SUM(D6:O6) -> 19881059
A7: 3012 | B7: Inntekter UE | C7: =P7/$P$8 -> 0.049501429 | D7: 120000 | E7: =D7 -> 120000 | F7: =E7 -> 120000 | G7: =F7 -> 120000 | H7: =G7 -> 120000 | I7: =H7 -> 120000 | J7: =I7 -> 120000 | K7: =J7 -> 120000 | L7: =K7 -> 120000 | ... O7: =N7 -> 120000 | P7: =SUM(D7:O7) -> 1440000
B8: Sum inntekter | C8: =P8/$P$8 -> 1 | D8: =SUM(D5:D7) -> 2493629.7 | E8: =SUM(E5:E7) -> 2570730.9 | F8: =SUM(F5:F7) -> 2687432.3 | G8: =SUM(G5:G7) -> 2103925 | H8: =SUM(H5:H7) -> 2618622.9 | I8: =SUM(I5:I7) -> 2618622.9 | J8: =SUM(J5:J7) -> 1435064.7 | K8: =SUM(K5:K7) -> 2329308.7 | ... P8: =SUM(P5:P7) -> 29090069 | IV8: =SUM(D8:IU8) -> 58180139
A10: VAREKOSTNADER
A11: 4010 | B11: Varekjøp byggearbeid | C11: 0.48 | D11: =D5*$C$11 -> 294407.1 | E11: =E5*$C$11 -> 345115.21 | F11: =F5*$C$11 -> 361549.27 | G11: =G5*$C$11 -> 279378.98 | H11: =H5*$C$11 -> 312247.09 | I11: =I5*$C$11 -> 312247.09 | J11: =J5*$C$11 -> 164340.58 | K11: =K5*$C$11 -> 276092.17 | ... O11: =O5*$C$11 -> 296634.74 | P11: =SUM(D11:O11) -> 3729125.1
A13: 4011 | B13: Varekjøp malerarbeid | C13: 0.13 | D13: =D6*$C$13 -> 228836.61 | E13: =E6*$C$13 -> 225126.31 | F13: =F6*$C$13 -> 235846.61 | G13: =G6*$C$13 -> 182245.11 | H13: =H6*$C$13 -> 240254.06 | I13: =I6*$C$13 -> 240254.06 | J13: =J6*$C$13 -> 126449.51 | K13: =K6*$C$13 -> 212435.17 | ... O13: =O6*$C$13 -> 181921.45 | P13: =SUM(D13:O13) -> 2584537.6 | Q13: =P13/P6 -> 0.13
A14: 4350 | B14: Produksjonsavfall | C14: =P14/$P$8 -> 0.0082502381 | D14: 20000 | E14: =D14 -> 20000 | F14: =E14 -> 20000 | G14: =F14 -> 20000 | H14: =G14 -> 20000 | I14: =H14 -> 20000 | J14: =I14 -> 20000 | K14: =J14 -> 20000 | L14: =K14 -> 20000 | ... O14: =N14 -> 20000 | P14: =SUM(D14:O14) -> 240000
A15: 4500 | B15: Innkjøpte tjenester (UE) | C15: =P15/$P$8 -> 0.045001299 | D15: =D7/1.1 -> 109090.91 | E15: =D15 -> 109090.91 | F15: =E15 -> 109090.91 | G15: =F15 -> 109090.91 | H15: =G15 -> 109090.91 | I15: =H15 -> 109090.91 | J15: =I15 -> 109090.91 | K15: =J15 -> 109090.91 | L15: =K15 -> 109090.91 | ... O15: =N15 -> 109090.91 | P15: =SUM(D15:O15) -> 1309090.9
A16: 4505 | B16: Leie stillas/utstyr/container | C16: =P16/$P$8 -> 0.015812956 | D16: 30000 | E16: =D16 -> 30000 | F16: =E16 -> 30000 | G16: =F16 -> 30000 | H16: 50000 | I16: =H16 -> 50000 | J16: =I16 -> 50000 | K16: =J16 -> 50000 | L16: =K16 -> 50000 | M16: 30000 | N16: =M16 -> 30000 | O16: =N16 -> 30000 | P16: =SUM(D16:O16) -> 460000
B17: Sum varekostnader | C17: =P17/$P$8 -> 0.28610292 | D17: =SUM(D11:D16) -> 682334.61 | E17: =SUM(E11:E16) -> 729332.43 | F17: =SUM(F11:F16) -> 756486.79 | G17: =SUM(G11:G16) -> 620715 | H17: =SUM(H11:H16) -> 731592.06 | I17: =SUM(I11:I16) -> 731592.06 | J17: =SUM(J11:J16) -> 469880.99 | K17: =SUM(K11:K16) -> 667618.25 | ... P17: =SUM(P11:P16) -> 8322753.7 | Q17: =P17/$P$8 -> 0.28610292
A19: DEKNINGSGRAD 1 | C19: =P19/$P$8 -> 0.71389708 | D19: =D8-D17 -> 1811295.1 | E19: =E8-E17 -> 1841398.4 | F19: =F8-F17 -> 1930945.6 | G19: =G8-G17 -> 1483210 | H19: =H8-H17 -> 1887030.9 | I19: =I8-I17 -> 1887030.9 | J19: =J8-J17 -> 965183.71 | K19: =K8-K17 -> 1661690.5 | ... O19: =O8-O17 -> 1499737.7 | P19: =SUM(D19:O19) -> 20767316
A21: LØNNSKOSTNADER
A22: 5000 | B22: Lønn til ansatte | C22: =P22/$P$8 -> 0.40619448 | D22: ='Areal - forutsetn.'!G39+'Areal - forutsetn.'!G40 -> 965582.82 | E22: ='Areal - forutsetn.'!H39+'Areal - forutsetn.'!H40 -> 961510.38 | F22: ='Areal - forutsetn.'!I39+'Areal - forutsetn.'!I40 -> 1057661.4 | G22: ='Areal - forutsetn.'!J39+'Areal - forutsetn.'!J40 -> 992981.68 | H22: ='Areal - forutsetn.'!K39+'Areal - forutsetn.'!K40 -> 1140071.2 | I22: ='Areal - forutsetn.'!L39+'Areal - forutsetn.'!L40 -> 1085766.7 | J22: ='Areal - forutsetn.'!M39+'Areal - forutsetn.'!M40 -> 542874.88 | K22: ='Areal - forutsetn.'!N39+'Areal - forutsetn.'!N40 -> 868599.82 | ... O22: ='Areal - forutsetn.'!R39+'Areal - forutsetn.'!R40 -> 964224.13 | P22: =SUM(D22:O22) -> 11816226
A23: 5001 | B23: Overtid | C23: =P23/$P$8 -> 0.0040619448 | D23: =D22*1% -> 9655.8282 | E23: =E22*1% -> 9615.1038 | F23: =F22*1% -> 10576.614 | G23: =G22*1% -> 9929.8168 | H23: =H22*1% -> 11400.712 | I23: =I22*1% -> 10857.667 | J23: =J22*1% -> 5428.7488 | K23: =K22*1% -> 8685.9982 | ... O23: =O22*1% -> 9642.2413 | P23: =SUM(D23:O23) -> 118162.26
A24: 5090 | B24: Feriepenger | C24: =P24/$P$8 -> 0.049230771 | D24: =(D22+D23)*12% -> 117028.64 | E24: =(E22+E23)*12% -> 116535.06 | F24: =(F22+F23)*12% -> 128188.56 | G24: =(G22+G23)*12% -> 120349.38 | H24: =(H22+H23)*12% -> 138176.63 | I24: =(I22+I23)*12% -> 131594.93 | J24: =(J22+J23)*12% -> 65796.436 | K24: =(K22+K23)*12% -> 105274.3 | ... O24: =(O22+O23)*12% -> 116863.96 | P24: =SUM(D24:O24) -> 1432126.6
A25: 5182 | B25: Arbeidsgiveravgift påløpne feriepenger | C25: =P25/$P$8 -> 0.0038892309 | D25: =SUM(D24*7.9%) -> 9245.2623 | E25: =SUM(E24*7.9%) -> 9206.2696 | F25: =SUM(F24*7.9%) -> 10126.897 | G25: =SUM(G24*7.9%) -> 9507.6009 | H25: =SUM(H24*7.9%) -> 10915.954 | I25: =SUM(I24*7.9%) -> 10395.999 | J25: =SUM(J24*7.9%) -> 5197.9184 | K25: =SUM(K24*7.9%) -> 8316.6695 | ... O25: =SUM(O24*7.9%) -> 9232.2532 | P25: =SUM(D25:O25) -> 113138
A26: 5400 | B26: Arbeidsgiveravgift | C26: =P26/$P$8 -> 0.032410258 | D26: =(D22+D23)*7.9% -> 77043.853 | E26: =(E22+E23)*7.9% -> 76718.914 | F26: =(F22+F23)*7.9% -> 84390.805 | G26: =(G22+G23)*7.9% -> 79230.008 | H26: =(H22+H23)*7.9% -> 90966.279 | I26: =(I22+I23)*7.9% -> 86633.327 | J26: =(J22+J23)*7.9% -> 43315.987 | K26: =(K22+K23)*7.9% -> 69305.579 | ... O26: =(O22+O23)*7.9% -> 76935.443 | P26: =SUM(D26:O26) -> 942816.65
B27: Sum lønnskostnader | C27: =P27/$P$8 -> 0.49578669 | D27: =SUM(D22:D26) -> 1178556.4 | E27: =SUM(E22:E26) -> 1173585.7 | F27: =SUM(F22:F26) -> 1290944.3 | G27: =SUM(G22:G26) -> 1211998.5 | H27: =SUM(H22:H26) -> 1391530.8 | I27: =SUM(I22:I26) -> 1325248.7 | J27: =SUM(J22:J26) -> 662613.97 | K27: =SUM(K22:K26) -> 1060182.4 | ... P27: =SUM(P22:P26) -> 14422469 | Q27: =P27/$P$8 -> 0.49578669
A29: ANDRE PERSONALKOSTNADER
A30: 5920 | B30: Yrkesskadeforsikring | C30: =P30/$P$8 -> 0.0012375357 | D30: 3000 | E30: =D30 -> 3000 | F30: =E30 -> 3000 | G30: =F30 -> 3000 | H30: =G30 -> 3000 | I30: =H30 -> 3000 | J30: =I30 -> 3000 | K30: =J30 -> 3000 | L30: =K30 -> 3000 | ... O30: =N30 -> 3000 | P30: =SUM(D30:O30) -> 36000
A31: 5945 | B31: Innskuddsbasert tjenestepensjon | C31: =P31/$P$8 -> 0.013810612 | D31: =SUM(D22*3.4/100) -> 32829.816 | E31: =SUM(E22*3.4/100) -> 32691.353 | F31: =SUM(F22*3.4/100) -> 35960.488 | G31: =SUM(G22*3.4/100) -> 33761.377 | H31: =SUM(H22*3.4/100) -> 38762.42 | I31: =SUM(I22*3.4/100) -> 36916.069 | J31: =SUM(J22*3.4/100) -> 18457.746 | K31: =SUM(K22*3.4/100) -> 29532.394 | ... O31: =SUM(O22*3.4/100) -> 32783.62 | P31: =SUM(D31:O31) -> 401751.68
A32: 5950 | B32: Kurskostnader | C32: =P32/$P$8 -> 0.0049501429 | D32: 12000 | E32: =D32 -> 12000 | F32: =E32 -> 12000 | G32: =F32 -> 12000 | H32: =G32 -> 12000 | I32: =H32 -> 12000 | J32: =I32 -> 12000 | K32: =J32 -> 12000 | L32: =K32 -> 12000 | ... O32: =N32 -> 12000 | P32: =SUM(D32:O32) -> 144000
A33: 5960 | B33: Bedriftshelsetjeneste | C33: =P33/$P$8 -> 0.00082502381 | D33: 2000 | E33: =D33 -> 2000 | F33: =E33 -> 2000 | G33: =F33 -> 2000 | H33: =G33 -> 2000 | I33: =H33 -> 2000 | J33: =I33 -> 2000 | K33: =J33 -> 2000 | L33: =K33 -> 2000 | ... O33: =N33 -> 2000 | P33: =SUM(D33:O33) -> 24000
A34: 5990 | B34: Andre personalkostnader | C34: =P34/$P$8 -> 0.0061876786 | D34: 15000 | E34: =D34 -> 15000 | F34: =E34 -> 15000 | G34: =F34 -> 15000 | H34: =G34 -> 15000 | I34: =H34 -> 15000 | J34: =I34 -> 15000 | K34: =J34 -> 15000 | L34: =K34 -> 15000 | ... O34: =N34 -> 15000 | P34: =SUM(D34:O34) -> 180000
B35: Sum andre personalkostnader | C35: =P35/$P$8 -> 0.027010993 | D35: =SUM(D30:D34) -> 64829.816 | E35: =SUM(E30:E34) -> 64691.353 | F35: =SUM(F30:F34) -> 67960.488 | G35: =SUM(G30:G34) -> 65761.377 | H35: =SUM(H30:H34) -> 70762.42 | I35: =SUM(I30:I34) -> 68916.069 | J35: =SUM(J30:J34) -> 50457.746 | K35: =SUM(K30:K34) -> 61532.394 | ... P35: =SUM(P30:P34) -> 785751.68
B37: SUM LØNNS- OG PERSONALKOSTNADER | D37: =D27+D35 -> 1243386.2 | E37: =E27+E35 -> 1238277.1 | F37: =F27+F35 -> 1358904.8 | G37: =G27+G35 -> 1277759.9 | H37: =H27+H35 -> 1462293.2 | I37: =I27+I35 -> 1394164.7 | J37: =J27+J35 -> 713071.72 | K37: =K27+K35 -> 1121714.8 | ... P37: =P27+P35 -> 15208221 | Q37: =P37/$P$8 -> 0.52279768
A39: DEKNINGSGRAD 2 | C39: =P39/$P$8 -> 0.1910994 | D39: =D19-D37 -> 567908.89 | E39: =E19-E37 -> 603121.36 | F39: =F19-F37 -> 572040.76 | G39: =G19-G37 -> 205450.14 | H39: =H19-H37 -> 424737.7 | I39: =I19-I37 -> 492866.15 | J39: =J19-J37 -> 252111.99 | K39: =K19-K37 -> 539975.7 | ... O39: =O19-O37 -> 258056.04 | P39: =SUM(D39:O39) -> 5559094.9 | Q39: =P39/$P$8 -> 0.1910994
A41: AVSKRIVNINGER
A42: 6000 | B42: Avskrivning maskiner mv | C42: =P42/$P$8 -> 0.0072189584 | D42: 17500 | E42: =D42 -> 17500 | F42: =E42 -> 17500 | G42: =F42 -> 17500 | H42: =G42 -> 17500 | I42: =H42 -> 17500 | J42: =I42 -> 17500 | K42: =J42 -> 17500 | L42: =K42 -> 17500 | ... O42: =N42 -> 17500 | P42: =SUM(D42:O42) -> 210000
B43: Sum avskrivninger | C43: =P43/$P$8 -> 0.0072189584 | D43: =SUM(D42:D42) -> 17500 | E43: =SUM(E42:E42) -> 17500 | F43: =SUM(F42:F42) -> 17500 | G43: =SUM(G42:G42) -> 17500 | H43: =SUM(H42:H42) -> 17500 | I43: =SUM(I42:I42) -> 17500 | J43: =SUM(J42:J42) -> 17500 | K43: =SUM(K42:K42) -> 17500 | ... P43: =SUM(P42:P42) -> 210000
A45: KOSTNADER LOKALER
A46: 6300 | B46: Leie lokaler | C46: =P46/$P$8 -> 0.012222563 | D46: =26936*1.1 -> 29629.6 | E46: =D46 -> 29629.6 | F46: =E46 -> 29629.6 | G46: =F46 -> 29629.6 | H46: =G46 -> 29629.6 | I46: =H46 -> 29629.6 | J46: =I46 -> 29629.6 | K46: =J46 -> 29629.6 | L46: =K46 -> 29629.6 | ... O46: =N46 -> 29629.6 | P46: =SUM(D46:O46) -> 355555.2
A47: 6301 | B47: Leie lokaler - Fauske | C47: =P47/$P$8 -> 0.0041044935 | D47: =29850/3 -> 9950 | E47: =D47 -> 9950 | F47: =E47 -> 9950 | G47: =F47 -> 9950 | H47: =G47 -> 9950 | I47: =H47 -> 9950 | J47: =I47 -> 9950 | K47: =J47 -> 9950 | L47: =K47 -> 9950 | ... O47: =N47 -> 9950 | P47: =SUM(D47:O47) -> 119400
A48: 6340 | B48: Strøm | C48: =P48/$P$8 -> 0.0011137821 | D48: =1800+900 -> 2700 | E48: =D48 -> 2700 | F48: =E48 -> 2700 | G48: =F48 -> 2700 | H48: =G48 -> 2700 | I48: =H48 -> 2700 | J48: =I48 -> 2700 | K48: =J48 -> 2700 | L48: =K48 -> 2700 | ... O48: =N48 -> 2700 | P48: =SUM(D48:O48) -> 32400
A49: 6360 | B49: Renhold | C49: =P49/$P$8 -> 0.00056307875 | D49: 1365 | E49: =D49 -> 1365 | F49: =E49 -> 1365 | G49: =F49 -> 1365 | H49: =G49 -> 1365 | I49: =H49 -> 1365 | J49: =I49 -> 1365 | K49: =J49 -> 1365 | L49: =K49 -> 1365 | ... O49: =N49 -> 1365 | P49: =SUM(D49:O49) -> 16380
A50: 6361 | B50: IT-drift | C50: =P50/$P$8 -> 0.00061876786 | D50: 1500 | E50: =D50 -> 1500 | F50: =E50 -> 1500 | G50: =F50 -> 1500 | H50: =G50 -> 1500 | I50: =H50 -> 1500 | J50: =I50 -> 1500 | K50: =J50 -> 1500 | L50: =K50 -> 1500 | ... O50: =N50 -> 1500 | P50: =SUM(D50:O50) -> 18000
...

Sheet Fritzøe - budsj 2020
A1: RESULTATBUDSJETT - 2020 | C1: BYGGMESTER FRITZØE AS
A3: Konto | B3: Kontonavn | C3: % | D3: Jan | E3: Feb | F3: Mar | G3: Apr | H3: Mai | I3: Jun | J3: Jul | K3: Aug | L3: Sep | M3: Okt | N3: Nov | O3: Des | P3: Total
A4: INNTEKTER
A5: 3010 | B5: Inntekter byggearbeid | D5: ='Fritzøe - forutsetn'!G52+'Fritzøe - forutsetn'!G53 -> 3123136.6 | E5: ='Fritzøe - forutsetn'!H52+'Fritzøe - forutsetn'!H53 -> 3010695.3 | F5: ='Fritzøe - forutsetn'!I52+'Fritzøe - forutsetn'!I53 -> 3823939.1 | G5: ='Fritzøe - forutsetn'!J52+'Fritzøe - forutsetn'!J53 -> 2987343 | H5: ='Fritzøe - forutsetn'!K52+'Fritzøe - forutsetn'!K53 -> 3649380.7 | I5: ='Fritzøe - forutsetn'!L52+'Fritzøe - forutsetn'!L53 -> 4027162.5 | J5: ='Fritzøe - forutsetn'!M52+'Fritzøe - forutsetn'!M53 -> 1979107.4 | K5: ='Fritzøe - forutsetn'!N52+'Fritzøe - forutsetn'!N53 -> 3380478.9 | ... O5: ='Fritzøe - forutsetn'!R52+'Fritzøe - forutsetn'!R53 -> 2872916.7 | P5: =SUM(D5:O5) -> 41043244
A6: 3012 | B6: Inntekter UE | C6: =P6/$P$7 -> 0.080124176 | D6: =D26*1.1+D19*1.1 -> 110000 | E6: =E26*1.1+E19*1.1 -> 110000 | F6: =F26*1.1+F19*1.1 -> 275000 | G6: =G26*1.1+G19*1.1 -> 330000 | H6: =H26*1.1+H19*1.1 -> 550000 | I6: =I26*1.1+I19*1.1 -> 330000 | J6: =J26*1.1+J19*1.1 -> 220000 | K6: =K26*1.1+K19*1.1 -> 330000 | ... O6: =O26*1.1+O19*1.1 -> 330000 | P6: =SUM(D6:O6) -> 3575000
B7: Sum inntekter | C7: =P7/$P$7 -> 1 | D7: =SUM(D5:D6) -> 3233136.6 | E7: =SUM(E5:E6) -> 3120695.3 | F7: =SUM(F5:F6) -> 4098939.1 | G7: =SUM(G5:G6) -> 3317343 | H7: =SUM(H5:H6) -> 4199380.7 | I7: =SUM(I5:I6) -> 4357162.5 | J7: =SUM(J5:J6) -> 2199107.4 | K7: =SUM(K5:K6) -> 3710478.9 | ... P7: =SUM(P5:P6) -> 44618244 | IV7: =SUM(D7:IU7) -> 89236487
A9: VAREKOSTNADER
A10: 4300
A11: 4300 | B11: Varekjøp Byggevarer | C11: =P11/$P$7 -> 0.27661657 | D11: ='Fritzøe - forutsetn'!G53/1.18 -> 939160.82 | E11: ='Fritzøe - forutsetn'!H53/1.18 -> 905348.5 | F11: ='Fritzøe - forutsetn'!I53/1.18 -> 1149899.7 | G11: ='Fritzøe - forutsetn'!J53/1.18 -> 898326.21 | H11: ='Fritzøe - forutsetn'!K53/1.18 -> 1097408.1 | I11: ='Fritzøe - forutsetn'!L53/1.18 -> 1211011.1 | J11: ='Fritzøe - forutsetn'!M53/1.18 -> 595138.92 | K11: ='Fritzøe - forutsetn'!N53/1.18 -> 1016546.4 | ... O11: ='Fritzøe - forutsetn'!R53/1.18 -> 863917 | P11: =SUM(D11:O11) -> 12342145 | Q11: =P11/$P$7 -> 0.27661657
A12: 4350 | B12: Produksjonsavfall | C12: =P12/$P$7 -> 0.020171121 | D12: 75000 | E12: =D12 -> 75000 | F12: =E12 -> 75000 | G12: =F12 -> 75000 | H12: =G12 -> 75000 | I12: =H12 -> 75000 | J12: =I12 -> 75000 | K12: =J12 -> 75000 | L12: =K12 -> 75000 | ... O12: =N12 -> 75000 | P12: =SUM(D12:O12) -> 900000
A13: 4500 | B13: Innkjøpte tjenester - Bemanning | C13: =P13/$P$7 -> 0 | D13: ='Fritzøe - forutsetn'!G76 -> 0 | E13: ='Fritzøe - forutsetn'!H76 -> 0 | F13: ='Fritzøe - forutsetn'!I76 -> 0 | G13: ='Fritzøe - forutsetn'!J76 -> 0 | H13: ='Fritzøe - forutsetn'!K76 -> 0 | I13: ='Fritzøe - forutsetn'!L76 -> 0 | J13: ='Fritzøe - forutsetn'!M76 -> 0 | K13: ='Fritzøe - forutsetn'!N76 -> 0 | ... O13: ='Fritzøe - forutsetn'!R76 -> 0 | P13: =SUM(D13:O13) -> 0
A14: 4501 | B14: Innkjøpte tjenester - Arkitekt/prosjektering | C14: =P14/$P$7 -> 0.00056030892 | D14: 0 | E14: 0 | G14: =F14 -> 0 | H14: 5000 | I14: =H14 -> 5000 | J14: =I14 -> 5000 | K14: =J14 -> 5000 | L14: =K14 -> 5000 | P14: =SUM(D14:O14) -> 25000
A15: 4502 | B15: Innkjøpte tjenester - Grunnarbeid | C15: =P15/$P$7 -> 0 | D15: 0 | E15: 0 | F15: 0 | G15: =F15 -> 0 | H15: 0 | I15: 0 | J15: 0 | K15: 0 | L15: 0 | M15: 0 | N15: 0 | O15: 0 | P15: =SUM(D15:O15) -> 0
A16: 4503 | B16: Innkjøpte tjenester - Kjøkken | C16: =P16/$P$7 -> 0.0036980389 | D16: 0 | E16: =D16 -> 0 | F16: =E16 -> 0 | G16: =F16 -> 0 | H16: =G16 -> 0 | I16: =H16 -> 0 | J16: =I16 -> 0 | K16: =J16 -> 0 | L16: 0 | M16: 55000 | N16: =M16 -> 55000 | O16: =N16 -> 55000 | P16: =SUM(D16:O16) -> 165000
A17: 4504 | B17: Innkjøpte tjenester - VVS | C17: =P17/$P$7 -> 0.0058272128 | D17: 0 | E17: =D17 -> 0 | F17: =E17 -> 0 | G17: =F17 -> 0 | I17: 60000 | K17: =J17 -> 0 | M17: 0 | N17: 100000 | O17: =N17 -> 100000 | P17: =SUM(D17:O17) -> 260000
A18: 4506 | B18: Innkjøpte tjenester - EL | C18: =P18/$P$7 -> 0.012999167 | D18: 20000 | E18: =D18 -> 20000 | F18: =E18 -> 20000 | G18: =F18 -> 20000 | H18: 200000 | I18: 60000 | J18: 20000 | K18: =J18 -> 20000 | L18: =K18 -> 20000 | M18: =L18 -> 20000 | N18: 80000 | O18: =N18 -> 80000 | P18: =SUM(D18:O18) -> 580000
A19: 4507 | B19: Innkjøpte tjenester - MAL | C19: =P19/$P$7 -> 0.049307185 | D19: 50000 | E19: =D19 -> 50000 | F19: 200000 | G19: =F19 -> 200000 | H19: =G19+200000 -> 400000 | I19: =G19 -> 200000 | J19: 100000 | K19: =I19 -> 200000 | L19: =K19 -> 200000 | M19: =L19 -> 200000 | N19: =M19 -> 200000 | O19: =N19 -> 200000 | P19: =SUM(D19:O19) -> 2200000
A20: 4508 | B20: Innkjøpte tjenester - Betong | C20: =P20/$P$7 -> 0 | E20: ='Fritzøe - forutsetn'!H83 -> 0 | F20: ='Fritzøe - forutsetn'!I83 -> 0 | G20: ='Fritzøe - forutsetn'!J83 -> 0 | J20: 0 | K20: =J20 -> 0 | L20: =K20 -> 0 | M20: =L20 -> 0 | N20: =M20 -> 0 | O20: =N20 -> 0 | P20: =SUM(D20:O20) -> 0
A21: 4510 | B21: Innkjøpte tjenester - Glass | C21: =P21/$P$7 -> 0 | D21: 0 | E21: =D21 -> 0 | F21: =E21 -> 0 | G21: =F21 -> 0 | H21: =G21 -> 0 | I21: =H21 -> 0 | J21: =I21 -> 0 | K21: =J21 -> 0 | L21: =K21 -> 0 | ... O21: =N21 -> 0 | P21: =SUM(D21:O21) -> 0
A22: 4511 | B22: Innkjøpte tjenester - Trapper | C22: =P22/$P$7 -> 0.0062754599 | D22: 0 | E22: =D22 -> 0 | F22: =E22 -> 0 | G22: =F22 -> 0 | H22: 100000 | J22: =I22 -> 0 | K22: =J22 -> 0 | L22: 60000 | M22: =L22 -> 60000 | N22: =M22 -> 60000 | O22: 0 | P22: =SUM(D22:O22) -> 280000
A23: 4512 | B23: Innkjøpte tjenester - Tak og tekking | C23: =P23/$P$7 -> 0.0060513364 | D23: 10000 | E23: =D23 -> 10000 | F23: =E23 -> 10000 | G23: =F23 -> 10000 | H23: =G23 -> 10000 | I23: =H23 -> 10000 | J23: =I23 -> 10000 | K23: 40000 | L23: =K23 -> 40000 | M23: =L23 -> 40000 | N23: =M23 -> 40000 | O23: =N23 -> 40000 | P23: =SUM(D23:O23) -> 270000
A24: 4513 | B24: Innkjøpte tjenester - Transport og kraning | C24: =P24/$P$7 -> 0.0040342242 | D24: 15000 | E24: =D24 -> 15000 | F24: =E24 -> 15000 | G24: =F24 -> 15000 | H24: =G24 -> 15000 | I24: =H24 -> 15000 | J24: =I24 -> 15000 | K24: =J24 -> 15000 | L24: =K24 -> 15000 | ... O24: =N24 -> 15000 | P24: =SUM(D24:O24) -> 180000
A25: 4514 | B25: Innkjøpte tjenester - Flisarbeider | C25: =P25/$P$7 -> 0.010085561 | D25: 0 | E25: =D25 -> 0 | F25: =E25 -> 0 | G25: 120000 | H25: =G25 -> 120000 | I25: 0 | J25: =I25 -> 0 | K25: =J25 -> 0 | L25: =K25 -> 0 | M25: 70000 | N25: =M25 -> 70000 | O25: =N25 -> 70000 | P25: =SUM(D25:O25) -> 450000
A26: 4515 | B26: Innkjøpte tjenester - FB | C26: =P26/$P$7 -> 0.023532975 | D26: 50000 | E26: =D26 -> 50000 | F26: 50000 | G26: 100000 | H26: =G26 -> 100000 | I26: =H26 -> 100000 | J26: =I26 -> 100000 | K26: 100000 | L26: =K26 -> 100000 | M26: =L26 -> 100000 | N26: =M26 -> 100000 | O26: =N26 -> 100000 | P26: =SUM(D26:O26) -> 1050000
A27: 4505 | B27: Leie stillas/utstyr/container | C27: =P27/$P$7 -> 0.020171121 | D27: 75000 | E27: =D27 -> 75000 | F27: =E27 -> 75000 | G27: =F27 -> 75000 | H27: =G27 -> 75000 | I27: =H27 -> 75000 | J27: =I27 -> 75000 | K27: =J27 -> 75000 | L27: =K27 -> 75000 | ... O27: =N27 -> 75000 | P27: =SUM(D27:O27) -> 900000
A28: 4509 | B28: Byggestrøm | C28: =P28/$P$7 -> 0.0048410691 | D28: 18000 | E28: =D28 -> 18000 | F28: =E28 -> 18000 | G28: =F28 -> 18000 | H28: =G28 -> 18000 | I28: =H28 -> 18000 | J28: =I28 -> 18000 | K28: =J28 -> 18000 | L28: =K28 -> 18000 | ... O28: =N28 -> 18000 | P28: =SUM(D28:O28) -> 216000
B29: Sum varekostnader | C29: =P29/$P$7 -> 0.44417135 | D29: =SUM(D10:D28) -> 1252160.8 | E29: =SUM(E10:E28) -> 1218348.5 | F29: =SUM(F10:F28) -> 1612899.7 | G29: =SUM(G10:G28) -> 1531326.2 | H29: =SUM(H10:H28) -> 2215408.1 | I29: =SUM(I10:I28) -> 1829011.1 | J29: =SUM(J10:J28) -> 1013138.9 | K29: =SUM(K10:K28) -> 1564546.4 | ... P29: =SUM(P10:P28) -> 19818145 | Q29: =P29/$P$7 -> 0.44417135
A31: DEKNINGSGRAD 1 | C31: =P31/$P$7 -> 0.55582865 | D31: =D7-D29 -> 1980975.8 | E31: =E7-E29 -> 1902346.8 | F31: =F7-F29 -> 2486039.4 | G31: =G7-G29 -> 1786016.8 | H31: =H7-H29 -> 1983972.6 | I31: =I7-I29 -> 2528151.4 | J31: =J7-J29 -> 1185968.5 | K31: =K7-K29 -> 2145932.5 | ... O31: =O7-O29 -> 1510999.7 | P31: =SUM(D31:O31) -> 24800098
A33: LØNNSKOSTNADER
A34: 5000 | B34: Lønn til ansatte | C34: =P34/$P$7 -> 0.32935997 | D34: ='Fritzøe - forutsetn'!G45+'Fritzøe - forutsetn'!G46 -> 1258808.5 | E34: ='Fritzøe - forutsetn'!H45+'Fritzøe - forutsetn'!H46 -> 1148522.3 | F34: ='Fritzøe - forutsetn'!I45+'Fritzøe - forutsetn'!I46 -> 1317823 | G34: ='Fritzøe - forutsetn'!J45+'Fritzøe - forutsetn'!J46 -> 1222192.5 | H34: ='Fritzøe - forutsetn'!K45+'Fritzøe - forutsetn'!K46 -> 1386417 | I34: ='Fritzøe - forutsetn'!L45+'Fritzøe - forutsetn'!L46 -> 1336047.1 | J34: ='Fritzøe - forutsetn'!M45+'Fritzøe - forutsetn'!M46 -> 692284.79 | K34: ='Fritzøe - forutsetn'!N45+'Fritzøe - forutsetn'!N46 -> 1076014.1 | ... O34: ='Fritzøe - forutsetn'!R45+'Fritzøe - forutsetn'!R46 -> 1149840.1 | P34: =SUM(D34:O34) -> 14695463
A35: 5001 | B35: Overtid | C35: =P35/$P$7 -> 0.0019761598 | D35: =D34*0.6% -> 7552.8513 | E35: =E34*0.6% -> 6891.1338 | F35: =F34*0.6% -> 7906.9382 | G35: =G34*0.6% -> 7333.1547 | H35: =H34*0.6% -> 8318.5022 | I35: =I34*0.6% -> 8016.2824 | J35: =J34*0.6% -> 4153.7087 | K35: =K34*0.6% -> 6456.0844 | ... O35: =O34*0.6% -> 6899.0408 | P35: =SUM(D35:O35) -> 88172.78
A36: 5011 | B36: Gangtid 7,5 - 15 km | C36: =P36/$P$7 -> 0.0056479139 | D36: 21000 | E36: =D36 -> 21000 | F36: =E36 -> 21000 | G36: =F36 -> 21000 | H36: =G36 -> 21000 | I36: =H36 -> 21000 | J36: =I36 -> 21000 | K36: =J36 -> 21000 | L36: =K36 -> 21000 | ... O36: =N36 -> 21000 | P36: =SUM(D36:O36) -> 252000
A37: 5092 | B37: Feriepenger | C37: =P37/$P$7 -> 0.040438085 | D37: =SUM(D34:D36)*12/100 -> 154483.37 | E37: =SUM(E34:E36)*12/100 -> 141169.61 | F37: =SUM(F34:F36)*12/100 -> 161607.6 | G37: =SUM(G34:G36)*12/100 -> 150063.07 | H37: =SUM(H34:H36)*12/100 -> 169888.27 | I37: =SUM(I34:I36)*12/100 -> 163807.6 | J37: =SUM(J34:J36)*12/100 -> 86092.62 | K37: =SUM(K34:K36)*12/100 -> 132416.42 | ... O37: =SUM(O34:O36)*12/100 -> 141328.7 | P37: =SUM(D37:O37) -> 1804276.3
A38: 5110 | B38: Sykepenger | C38: =P38/$P$7 -> 0 | P38: =SUM(D38:O38) -> 0
A39: 5200 | B39: Fri bil | C39: =P39/$P$7 -> 0.0021515863 | D39: 8000 | E39: =D39 -> 8000 | F39: =E39 -> 8000 | G39: =F39 -> 8000 | H39: =G39 -> 8000 | I39: =H39 -> 8000 | J39: =I39 -> 8000 | K39: =J39 -> 8000 | L39: =K39 -> 8000 | ... O39: =N39 -> 8000 | P39: =SUM(D39:O39) -> 96000
A40: 5330 | B40: Styrehonorar | C40: =P40/$P$7 -> 0 | P40: =SUM(D40:O40) -> 0
A41: 5400 | B41: Arbeidsgiveravgift | C41: =P41/$P$7 -> 0.026621739 | D41: =SUM(D34:D36)*7.9% -> 101701.55 | E41: =SUM(E34:E36)*7.9% -> 92936.662 | F41: =SUM(F34:F36)*7.9% -> 106391.67 | G41: =SUM(G34:G36)*7.9% -> 98791.523 | H41: =SUM(H34:H36)*7.9% -> 111843.11 | I41: =SUM(I34:I36)*7.9% -> 107840 | J41: =SUM(J34:J36)*7.9% -> 56677.641 | K41: =SUM(K34:K36)*7.9% -> 87174.142 | ... O41: =SUM(O34:O36)*7.9% -> 93041.394 | P41: =SUM(D41:O41) -> 1187815.2
A42: 5405 | B42: Arbeidsgiveravgift påløpne feriepenger | C42: =P42/$P$7 -> 0.0031946087 | D42: =SUM(D37*7.9%) -> 12204.186 | E42: =SUM(E37*7.9%) -> 11152.399 | F42: =SUM(F37*7.9%) -> 12767 | G42: =SUM(G37*7.9%) -> 11854.983 | H42: =SUM(H37*7.9%) -> 13421.173 | I42: =SUM(I37*7.9%) -> 12940.801 | J42: =SUM(J37*7.9%) -> 6801.317 | K42: =SUM(K37*7.9%) -> 10460.897 | ... O42: =SUM(O37*7.9%) -> 11164.967 | P42: =SUM(D42:O42) -> 142537.83
A43: 5700 | B43: Lærlingetilskudd | C43: =P43/$P$7 -> -0.0010757931 | D43: -8000 | E43: =D43 -> -8000 | F43: =E43 -> -8000 | G43: =F43 -> -8000 | H43: =G43 -> -8000 | I43: =H43 -> -8000 | P43: =SUM(D43:O43) -> -48000
B44: Sum lønnskostnader | C44: =P44/$P$7 -> 0.40831427 | D44: =SUM(D34:D43) -> 1555750.5 | E44: =SUM(E34:E43) -> 1421672.1 | F44: =SUM(F34:F43) -> 1627496.2 | G44: =SUM(G34:G43) -> 1511235.2 | H44: =SUM(H34:H43) -> 1710888.1 | I44: =SUM(I34:I43) -> 1649651.8 | J44: =SUM(J34:J43) -> 875010.08 | K44: =SUM(K34:K43) -> 1341521.6 | ... P44: =SUM(P34:P43) -> 18218265
...

Sheet KONSERN - Budsjett 2019
A1: RESULTATBUDSJETT - 2020 | C1: AREAL BYGGSERVICE, BYGGMESTER FRITZØE OG BLIKKPROFFEN
A2: Administrasjonens forslag - ikke styrebehandlet
A3: Konto | B3: Kontonavn | C3: % | D3: Jan | E3: Feb | F3: Mar | G3: Apr | H3: Mai | I3: Jun | J3: Jul | K3: Aug | L3: Sep | M3: Okt | N3: Nov | O3: Des | P3: Total
A4: INNTEKTER
B5: Areal Byggservice | C5: =P5/$P$7 -> 0.3946647 | D5: ='Areal - Budsjett 2020'!D8 -> 2493629.7 | E5: ='Areal - Budsjett 2020'!E8 -> 2570730.9 | F5: ='Areal - Budsjett 2020'!F8 -> 2687432.3 | G5: ='Areal - Budsjett 2020'!G8 -> 2103925 | H5: ='Areal - Budsjett 2020'!H8 -> 2618622.9 | I5: ='Areal - Budsjett 2020'!I8 -> 2618622.9 | J5: ='Areal - Budsjett 2020'!J8 -> 1435064.7 | K5: ='Areal - Budsjett 2020'!K8 -> 2329308.7 | ... O5: ='Areal - Budsjett 2020'!O8 -> 2137384.8 | P5: =SUM(D5:O5) -> 29090069
B6: Byggmester Fritzøe | C6: =P6/$P$7 -> 0.6053353 | D6: ='Fritzøe - budsj 2020'!D7 -> 3233136.6 | E6: ='Fritzøe - budsj 2020'!E7 -> 3120695.3 | F6: ='Fritzøe - budsj 2020'!F7 -> 4098939.1 | G6: ='Fritzøe - budsj 2020'!G7 -> 3317343 | H6: ='Fritzøe - budsj 2020'!H7 -> 4199380.7 | I6: ='Fritzøe - budsj 2020'!I7 -> 4357162.5 | J6: ='Fritzøe - budsj 2020'!J7 -> 2199107.4 | K6: ='Fritzøe - budsj 2020'!K7 -> 3710478.9 | ... O6: ='Fritzøe - budsj 2020'!O7 -> 3202916.7 | P6: =SUM(D6:O6) -> 44618244
B7: Sum inntekter | C7: =P7/$P$7 -> 1 | D7: =SUM(D5:D6) -> 5726766.3 | E7: =SUM(E5:E6) -> 5691426.1 | F7: =SUM(F5:F6) -> 6786371.5 | G7: =SUM(G5:G6) -> 5421268 | H7: =SUM(H5:H6) -> 6818003.6 | I7: =SUM(I5:I6) -> 6975785.4 | J7: =SUM(J5:J6) -> 3634172.1 | K7: =SUM(K5:K6) -> 6039787.6 | ... P7: =SUM(P5:P6) -> 73708313 | IV7: =SUM(D7:IU7) -> 1.4741663e+08
A9: VAREKOSTNADER
B10: Areal Byggservice | C10: =P10/P5 -> 0.28610292 | D10: ='Areal - Budsjett 2020'!D17 -> 682334.61 | E10: ='Areal - Budsjett 2020'!E17 -> 729332.43 | F10: ='Areal - Budsjett 2020'!F17 -> 756486.79 | G10: ='Areal - Budsjett 2020'!G17 -> 620715 | H10: ='Areal - Budsjett 2020'!H17 -> 731592.06 | I10: ='Areal - Budsjett 2020'!I17 -> 731592.06 | J10: ='Areal - Budsjett 2020'!J17 -> 469880.99 | K10: ='Areal - Budsjett 2020'!K17 -> 667618.25 | ... O10: ='Areal - Budsjett 2020'!O17 -> 637647.1 | P10: =SUM(D10:O10) -> 8322753.7
B11: Byggmester Fritzøe | C11: =P11/P6 -> 0.44417135 | D11: ='Fritzøe - budsj 2020'!D29 -> 1252160.8 | E11: ='Fritzøe - budsj 2020'!E29 -> 1218348.5 | F11: ='Fritzøe - budsj 2020'!F29 -> 1612899.7 | G11: ='Fritzøe - budsj 2020'!G29 -> 1531326.2 | H11: ='Fritzøe - budsj 2020'!H29 -> 2215408.1 | I11: ='Fritzøe - budsj 2020'!I29 -> 1829011.1 | J11: ='Fritzøe - budsj 2020'!J29 -> 1013138.9 | K11: ='Fritzøe - budsj 2020'!K29 -> 1564546.4 | ... O11: ='Fritzøe - budsj 2020'!O29 -> 1691917 | P11: =SUM(D11:O11) -> 19818145
B12: Sum varekostnader | C12: =P12/P7 -> 0.38178732 | D12: =SUM(D10:D11) -> 1934495.4 | E12: =SUM(E10:E11) -> 1947680.9 | F12: =SUM(F10:F11) -> 2369386.5 | G12: =SUM(G10:G11) -> 2152041.2 | H12: =SUM(H10:H11) -> 2947000.1 | I12: =SUM(I10:I11) -> 2560603.2 | J12: =SUM(J10:J11) -> 1483019.9 | K12: =SUM(K10:K11) -> 2232164.7 | ... P12: =SUM(P10:P11) -> 28140899
A14: DEKNINGSGRAD 1 | C14: =P14/$P$7 -> 0.61821268 | D14: =D7-D12 -> 3792270.9 | E14: =E7-E12 -> 3743745.2 | F14: =F7-F12 -> 4416985 | G14: =G7-G12 -> 3269226.8 | H14: =H7-H12 -> 3871003.5 | I14: =I7-I12 -> 4415182.2 | J14: =J7-J12 -> 2151152.2 | K14: =K7-K12 -> 3807623 | ... O14: =O7-O12 -> 3010737.4 | P14: =SUM(D14:O14) -> 45567414
A16: LØNN OG PERSONALKOSTNADER
B17: Areal Byggservice | C17: =P17/$P$5 -> 0.52279768 | D17: ='Areal - Budsjett 2020'!D37 -> 1243386.2 | E17: ='Areal - Budsjett 2020'!E37 -> 1238277.1 | F17: ='Areal - Budsjett 2020'!F37 -> 1358904.8 | G17: ='Areal - Budsjett 2020'!G37 -> 1277759.9 | H17: ='Areal - Budsjett 2020'!H37 -> 1462293.2 | I17: ='Areal - Budsjett 2020'!I37 -> 1394164.7 | J17: ='Areal - Budsjett 2020'!J37 -> 713071.72 | K17: ='Areal - Budsjett 2020'!K37 -> 1121714.8 | ... O17: ='Areal - Budsjett 2020'!O37 -> 1241681.6 | P17: =SUM(D17:O17) -> 15208221
B18: Byggmester Fritzøe | C18: =P18/$P$6 -> 0.42317061 | D18: ='Fritzøe - budsj 2020'!D54 -> 1612014.8 | E18: ='Fritzøe - budsj 2020'!E54 -> 1474627.8 | F18: ='Fritzøe - budsj 2020'!F54 -> 1685530.9 | G18: ='Fritzøe - budsj 2020'!G54 -> 1566401 | H18: ='Fritzøe - budsj 2020'!H54 -> 1770980.6 | I18: ='Fritzøe - budsj 2020'!I54 -> 1708233.2 | J18: ='Fritzøe - budsj 2020'!J54 -> 914278.62 | K18: ='Fritzøe - budsj 2020'!K54 -> 1392302 | ... O18: ='Fritzøe - budsj 2020'!O54 -> 1484269.4 | P18: =SUM(D18:O18) -> 18881129
B19: Sum lønn og personalkostnader | C19: =P19/$P$7 -> 0.4624899 | D19: =SUM(D17:D18) -> 2855401 | E19: =SUM(E17:E18) -> 2712904.9 | F19: =SUM(F17:F18) -> 3044435.7 | G19: =SUM(G17:G18) -> 2844160.8 | H19: =SUM(H17:H18) -> 3233273.8 | I19: =SUM(I17:I18) -> 3102397.9 | J19: =SUM(J17:J18) -> 1627350.3 | K19: =SUM(K17:K18) -> 2514016.8 | ... P19: =SUM(P17:P18) -> 34089350
A21: AVSKRIVNINGER
B22: Areal Byggservice | C22: =P22/$P$5 -> 0.0072189584 | D22: ='Areal - Budsjett 2020'!D43 -> 17500 | E22: ='Areal - Budsjett 2020'!E43 -> 17500 | F22: ='Areal - Budsjett 2020'!F43 -> 17500 | G22: ='Areal - Budsjett 2020'!G43 -> 17500 | H22: ='Areal - Budsjett 2020'!H43 -> 17500 | I22: ='Areal - Budsjett 2020'!I43 -> 17500 | J22: ='Areal - Budsjett 2020'!J43 -> 17500 | K22: ='Areal - Budsjett 2020'!K43 -> 17500 | ... O22: ='Areal - Budsjett 2020'!O43 -> 17500 | P22: =SUM(D22:O22) -> 210000
B23: Byggmester Fritzøe | C23: =P23/$P$6 -> 0.0053789657 | D23: ='Fritzøe - budsj 2020'!D60 -> 20000 | E23: ='Fritzøe - budsj 2020'!E60 -> 20000 | F23: ='Fritzøe - budsj 2020'!F60 -> 20000 | G23: ='Fritzøe - budsj 2020'!G60 -> 20000 | H23: ='Fritzøe - budsj 2020'!H60 -> 20000 | I23: ='Fritzøe - budsj 2020'!I60 -> 20000 | J23: ='Fritzøe - budsj 2020'!J60 -> 20000 | K23: ='Fritzøe - budsj 2020'!K60 -> 20000 | ... O23: ='Fritzøe - budsj 2020'!O60 -> 20000 | P23: =SUM(D23:O23) -> 240000
B24: Sum avskrivninger | C24: =P24/$P$7 -> 0.0061051458 | D24: =SUM(D22:D23) -> 37500 | E24: =SUM(E22:E23) -> 37500 | F24: =SUM(F22:F23) -> 37500 | G24: =SUM(G22:G23) -> 37500 | H24: =SUM(H22:H23) -> 37500 | I24: =SUM(I22:I23) -> 37500 | J24: =SUM(J22:J23) -> 37500 | K24: =SUM(K22:K23) -> 37500 | ... P24: =SUM(P22:P23) -> 450000
A26: KOSTNADER LOKALER
B27: Areal Byggservice | C27: =P27/$P$5 -> 0.019653965 | D27: ='Areal - Budsjett 2020'!D52 -> 49144.6 | E27: ='Areal - Budsjett 2020'!E52 -> 49144.6 | F27: ='Areal - Budsjett 2020'!F52 -> 49144.6 | G27: ='Areal - Budsjett 2020'!G52 -> 49144.6 | H27: ='Areal - Budsjett 2020'!H52 -> 49144.6 | I27: ='Areal - Budsjett 2020'!I52 -> 49144.6 | J27: ='Areal - Budsjett 2020'!J52 -> 46144.6 | K27: ='Areal - Budsjett 2020'!K52 -> 46144.6 | ... O27: ='Areal - Budsjett 2020'!O52 -> 46144.6 | P27: =SUM(D27:O27) -> 571735.2
B28: Byggmester Fritzøe | C28: =P28/$P$6 -> 0.0088701833 | D28: ='Fritzøe - budsj 2020'!D70 -> 34481 | E28: ='Fritzøe - budsj 2020'!E70 -> 34481 | F28: ='Fritzøe - budsj 2020'!F70 -> 34481 | G28: ='Fritzøe - budsj 2020'!G70 -> 34481 | H28: ='Fritzøe - budsj 2020'!H70 -> 34481 | I28: ='Fritzøe - budsj 2020'!I70 -> 34481 | J28: ='Fritzøe - budsj 2020'!J70 -> 31481 | K28: ='Fritzøe - budsj 2020'!K70 -> 31481 | ... O28: ='Fritzøe - budsj 2020'!O70 -> 31481 | P28: =SUM(D28:O28) -> 395772
B29: Sum kostnader lokaler | C29: =P29/$P$7 -> 0.013126161 | D29: =SUM(D27:D28) -> 83625.6 | E29: =SUM(E27:E28) -> 83625.6 | F29: =SUM(F27:F28) -> 83625.6 | G29: =SUM(G27:G28) -> 83625.6 | H29: =SUM(H27:H28) -> 83625.6 | I29: =SUM(I27:I28) -> 83625.6 | J29: =SUM(J27:J28) -> 77625.6 | K29: =SUM(K27:K28) -> 77625.6 | ... P29: =SUM(P27:P28) -> 967507.2
A31: LEIE MASKINER OG UTSTYR
B32: Areal Byggservice | C32: =P32/$P$5 -> 0.015240115 | D32: ='Areal - Budsjett 2020'!D65 -> 37536 | E32: ='Areal - Budsjett 2020'!E65 -> 37536 | F32: ='Areal - Budsjett 2020'!F65 -> 37536 | G32: ='Areal - Budsjett 2020'!G65 -> 37536 | H32: ='Areal - Budsjett 2020'!H65 -> 37536 | I32: ='Areal - Budsjett 2020'!I65 -> 37536 | J32: ='Areal - Budsjett 2020'!J65 -> 37536 | K32: ='Areal - Budsjett 2020'!K65 -> 37536 | ... O32: ='Areal - Budsjett 2020'!O65 -> 37212 | P32: =SUM(D32:O32) -> 443336
B33: Byggmester Fritzøe | C33: =P33/$P$6 -> 0.0081617736 | D33: ='Fritzøe - budsj 2020'!D79 -> 30347 | E33: ='Fritzøe - budsj 2020'!E79 -> 30347 | F33: ='Fritzøe - budsj 2020'!F79 -> 30347 | G33: ='Fritzøe - budsj 2020'!G79 -> 30347 | H33: ='Fritzøe - budsj 2020'!H79 -> 30347 | I33: ='Fritzøe - budsj 2020'!I79 -> 30347 | J33: ='Fritzøe - budsj 2020'!J79 -> 30347 | K33: ='Fritzøe - budsj 2020'!K79 -> 30347 | ... O33: ='Fritzøe - budsj 2020'!O79 -> 30347 | P33: =SUM(D33:O33) -> 364164
B34: Sum leie maskiner og utstyr | C34: =P34/$P$7 -> 0.010955345 | D34: =SUM(D32:D33) -> 67883 | E34: =SUM(E32:E33) -> 67883 | F34: =SUM(F32:F33) -> 67883 | G34: =SUM(G32:G33) -> 67883 | H34: =SUM(H32:H33) -> 67883 | I34: =SUM(I32:I33) -> 67883 | J34: =SUM(J32:J33) -> 67883 | K34: =SUM(K32:K33) -> 67883 | ... P34: =SUM(P32:P33) -> 807500
A36: KOSTNADSFØRTE ANSKAFFELSER
B37: Areal Byggservice | C37: =P37/$P$5 -> 0.013406637 | D37: ='Areal - Budsjett 2020'!D73 -> 32500 | E37: ='Areal - Budsjett 2020'!E73 -> 32500 | F37: ='Areal - Budsjett 2020'!F73 -> 32500 | G37: ='Areal - Budsjett 2020'!G73 -> 32500 | H37: ='Areal - Budsjett 2020'!H73 -> 32500 | I37: ='Areal - Budsjett 2020'!I73 -> 32500 | J37: ='Areal - Budsjett 2020'!J73 -> 32500 | K37: ='Areal - Budsjett 2020'!K73 -> 32500 | ... O37: ='Areal - Budsjett 2020'!O73 -> 32500 | P37: =SUM(D37:O37) -> 390000
B38: Byggmester Fritzøe | C38: =P38/$P$6 -> 0.014254259 | D38: ='Fritzøe - budsj 2020'!D88 -> 53000 | E38: ='Fritzøe - budsj 2020'!E88 -> 53000 | F38: ='Fritzøe - budsj 2020'!F88 -> 53000 | G38: ='Fritzøe - budsj 2020'!G88 -> 53000 | H38: ='Fritzøe - budsj 2020'!H88 -> 53000 | I38: ='Fritzøe - budsj 2020'!I88 -> 53000 | J38: ='Fritzøe - budsj 2020'!J88 -> 53000 | K38: ='Fritzøe - budsj 2020'!K88 -> 53000 | ... O38: ='Fritzøe - budsj 2020'!O88 -> 53000 | P38: =SUM(D38:O38) -> 636000
B39: Sum kostnadsførte anskaffelser | C39: =P39/$P$7 -> 0.013919733 | D39: =SUM(D37:D38) -> 85500 | E39: =SUM(E37:E38) -> 85500 | F39: =SUM(F37:F38) -> 85500 | G39: =SUM(G37:G38) -> 85500 | H39: =SUM(H37:H38) -> 85500 | I39: =SUM(I37:I38) -> 85500 | J39: =SUM(J37:J38) -> 85500 | K39: =SUM(K37:K38) -> 85500 | ... P39: =SUM(P37:P38) -> 1026000
A41: REPARASJONER OG VEDLIKEHOLD
B42: Areal Byggservice | C42: =P42/$P$5 -> 0.00082502381 | D42: ='Areal - Budsjett 2020'!D77 -> 2000 | E42: ='Areal - Budsjett 2020'!E77 -> 2000 | F42: ='Areal - Budsjett 2020'!F77 -> 2000 | G42: ='Areal - Budsjett 2020'!G77 -> 2000 | H42: ='Areal - Budsjett 2020'!H77 -> 2000 | I42: ='Areal - Budsjett 2020'!I77 -> 2000 | J42: ='Areal - Budsjett 2020'!J77 -> 2000 | K42: ='Areal - Budsjett 2020'!K77 -> 2000 | ... O42: ='Areal - Budsjett 2020'!O77 -> 2000 | P42: =SUM(D42:O42) -> 24000
B43: Byggmester Fritzøe | C43: =P43/$P$6 -> 0.00067237071 | D43: ='Fritzøe - budsj 2020'!D92 -> 2500 | E43: ='Fritzøe - budsj 2020'!E92 -> 2500 | F43: ='Fritzøe - budsj 2020'!F92 -> 2500 | G43: ='Fritzøe - budsj 2020'!G92 -> 2500 | H43: ='Fritzøe - budsj 2020'!H92 -> 2500 | I43: ='Fritzøe - budsj 2020'!I92 -> 2500 | J43: ='Fritzøe - budsj 2020'!J92 -> 2500 | K43: ='Fritzøe - budsj 2020'!K92 -> 2500 | ... O43: ='Fritzøe - budsj 2020'!O92 -> 2500 | P43: =SUM(D43:O43) -> 30000
B44: Sum reparasjoner og vedlikehold | C44: =P44/$P$7 -> 0.0007326175 | D44: =SUM(D42:D43) -> 4500 | E44: =SUM(E42:E43) -> 4500 | F44: =SUM(F42:F43) -> 4500 | G44: =SUM(G42:G43) -> 4500 | H44: =SUM(H42:H43) -> 4500 | I44: =SUM(I42:I43) -> 4500 | J44: =SUM(J42:J43) -> 4500 | K44: =SUM(K42:K43) -> 4500 | ... P44: =SUM(P42:P43) -> 54000
A46: EKSTERNE HONORARER / KONSERN
B47: Areal Byggservice | C47: =P47/$P$5 -> 0.032588441 | D47: ='Areal - Budsjett 2020'!D84 -> 79000 | E47: ='Areal - Budsjett 2020'!E84 -> 79000 | F47: ='Areal - Budsjett 2020'!F84 -> 79000 | G47: ='Areal - Budsjett 2020'!G84 -> 79000 | H47: ='Areal - Budsjett 2020'!H84 -> 79000 | I47: ='Areal - Budsjett 2020'!I84 -> 79000 | J47: ='Areal - Budsjett 2020'!J84 -> 79000 | K47: ='Areal - Budsjett 2020'!K84 -> 79000 | ... O47: ='Areal - Budsjett 2020'!O84 -> 79000 | P47: =SUM(D47:O47) -> 948000
B48: Byggmester Fritzøe | C48: =P48/$P$6 -> 0.030794578 | D48: ='Fritzøe - budsj 2020'!D99 -> 114500 | E48: ='Fritzøe - budsj 2020'!E99 -> 114500 | F48: ='Fritzøe - budsj 2020'!F99 -> 114500 | G48: ='Fritzøe - budsj 2020'!G99 -> 114500 | H48: ='Fritzøe - budsj 2020'!H99 -> 114500 | I48: ='Fritzøe - budsj 2020'!I99 -> 114500 | J48: ='Fritzøe - budsj 2020'!J99 -> 114500 | K48: ='Fritzøe - budsj 2020'!K99 -> 114500 | ... O48: ='Fritzøe - budsj 2020'!O99 -> 114500 | P48: =SUM(D48:O48) -> 1374000
B49: Sum eksterne honorarer | C49: =P49/$P$7 -> 0.031502553 | D49: =SUM(D47:D48) -> 193500 | E49: =SUM(E47:E48) -> 193500 | F49: =SUM(F47:F48) -> 193500 | G49: =SUM(G47:G48) -> 193500 | H49: =SUM(H47:H48) -> 193500 | I49: =SUM(I47:I48) -> 193500 | J49: =SUM(J47:J48) -> 193500 | K49: =SUM(K47:K48) -> 193500 | ... P49: =SUM(P47:P48) -> 2322000
...

Sheet Areal - forutsetn.
A1: Forutsetninger omsetning og lønn | G1: 1 | H1: 0 | I1: 0 | J1: 3 | K1: 2 | L1: 1 | M1: 0 | N1: 0 | O1: 0 | P1: 0 | Q1: 0 | R1: 1 | S1: =SUM(G1:R1) -> 8 | T1: Bev Helligd
G2: 22 | H2: 20 | I2: 22 | J2: 19 | K2: 19 | L2: 21 | M2: 23 | N2: 21 | O2: 22 | P2: 22 | Q2: 21 | R2: 22 | S2: =SUM(G2:R2) -> 254 | T2: Arbeidsdager
J3: 2 | L3: 2 | M3: 13 | N3: 5 | R3: 3 | S3: =SUM(G3:R3) -> 25 | T3: feriedager
A4: Ordinære time | B4: Timelønn | C4: Snitt Dagtimer | D4: M | E4: B | F4: A | G4: Jan | H4: Feb | I4: Mar | J4: Apr | K4: Mai | L4: Jun | M4: Jul | N4: Aug | O4: Sep | P4: Okt | Q4: Nov | R4: Des | S4: Total
A5: Jan Roger Nikolaisen | B5: =(57500+6000)/162.5 -> 390.76923 | C5: 7.5 | D5: 0 | E5: 0 | F5: 1 | G5: =(G$2-G$3)*$C5 -> 165 | H5: =(H$2-H$3)*$C5 -> 150 | I5: =(I$2-I$3)*$C5 -> 165 | J5: =(J$2-J$3)*$C5 -> 127.5 | K5: =(K$2-K$3)*$C5 -> 142.5 | L5: =(L$2-L$3)*$C5 -> 142.5 | M5: =(M$2-M$3)*$C5 -> 75 | N5: =(N$2-N$3)*$C5 -> 120 | ... R5: =(R$2-R$3)*$C5 -> 142.5 | S5: =SUM(G5:R5) -> 1717.5
A6: Richard Sandåker | B6: =(50000+6000)/162.5 -> 344.61538 | C6: 7.5 | E6: 0.3 | F6: 0.7 | G6: =(G$2-G$3)*$C6 -> 165 | H6: =(H$2-H$3)*$C6 -> 150 | I6: =(I$2-I$3)*$C6 -> 165 | J6: =(J$2-J$3)*$C6 -> 127.5 | K6: =(K$2-K$3)*$C6 -> 142.5 | L6: =(L$2-L$3)*$C6 -> 142.5 | M6: =(M$2-M$3)*$C6 -> 75 | N6: =(N$2-N$3)*$C6 -> 120 | ... R6: =(R$2-R$3)*$C6 -> 142.5 | S6: =SUM(G6:R6) -> 1717.5
A7: Thomas Gravrok | B7: =591600/12/162.5 -> 303.38462 | C7: =7.5 -> 7.5 | D7: 0.4 | E7: 0.1 | F7: 0.5 | G7: =(G$2-G$3)*$C7 -> 165 | H7: =(H$2-H$3)*$C7 -> 150 | I7: =(I$2-I$3)*$C7 -> 165 | J7: =(J$2-J$3)*$C7 -> 127.5 | K7: =(K$2-K$3)*$C7 -> 142.5 | L7: =(L$2-L$3)*$C7 -> 142.5 | M7: =(M$2-M$3)*$C7 -> 75 | N7: =(N$2-N$3)*$C7 -> 120 | ... R7: =(R$2-R$3)*$C7 -> 142.5 | S7: =SUM(G7:R7) -> 1717.5
A8: Johnny Bruun | B8: 260 | C8: 7.5 | D8: 0.7 | F8: 0.3 | G8: =(G$2-G$3)*$C8 -> 165 | H8: =(H$2-H$3)*$C8 -> 150 | I8: =(I$2-I$3)*$C8 -> 165 | J8: =(J$2-J$3)*$C8 -> 127.5 | K8: =(K$2-K$3)*$C8 -> 142.5 | L8: =(L$2-L$3)*$C8 -> 142.5 | M8: =(M$2-M$3)*$C8 -> 75 | N8: =(N$2-N$3)*$C8 -> 120 | ... R8: =(R$2-R$3)*$C8 -> 142.5 | S8: =SUM(G8:R8) -> 1717.5
A9: Stanislaw Kmak | B9: 248 | C9: =7.5*1.15 -> 8.625 | D9: 0.2 | E9: 0.8 | G9: 95 | H9: =(H$2-H$3)*$C9 -> 172.5 | I9: =(I$2-I$3)*$C9 -> 189.75 | J9: =(J$2-J$3)*$C9 -> 146.625 | K9: =(K$2-K$3)*$C9 -> 163.875 | L9: =(L$2-L$3)*$C9 -> 163.875 | M9: =(M$2-M$3)*$C9 -> 86.25 | N9: =(N$2-N$3)*$C9 -> 138 | O9: =(O$2-O$3)*$C9 -> 189.75 | ... R9: =(R$2-R$3)*$C9 -> 163.875 | S9: =SUM(G9:R9) -> 1880.375
A10: Gzregorz Kurcharski (Bolek) | B10: 248 | C10: =7.5*1.15 -> 8.625 | D10: 0.2 | E10: 0.8 | G10: 95 | H10: =(H$2-H$3)*$C10 -> 172.5 | I10: =(I$2-I$3)*$C10 -> 189.75 | J10: =(J$2-J$3)*$C10 -> 146.625 | K10: =(K$2-K$3)*$C10 -> 163.875 | L10: =(L$2-L$3)*$C10 -> 163.875 | M10: =(M$2-M$3)*$C10 -> 86.25 | N10: =(N$2-N$3)*$C10 -> 138 | O10: =(O$2-O$3)*$C10 -> 189.75 | ... R10: =(R$2-R$3)*$C10 -> 163.875 | S10: =SUM(G10:R10) -> 1880.375
A11: Piotr Kmak | B11: 233 | C11: =7.5*1.15 -> 8.625 | D11: 0.5 | E11: 0.5 | G11: 40 | H11: =(H$2-H$3)*$C11 -> 172.5 | I11: =(I$2-I$3)*$C11 -> 189.75 | J11: =(J$2-J$3)*$C11 -> 146.625 | K11: =(K$2-K$3)*$C11 -> 163.875 | L11: =(L$2-L$3)*$C11 -> 163.875 | M11: =(M$2-M$3)*$C11 -> 86.25 | N11: =(N$2-N$3)*$C11 -> 138 | O11: =(O$2-O$3)*$C11 -> 189.75 | ... R11: =(R$2-R$3)*$C11 -> 163.875 | S11: =SUM(G11:R11) -> 1825.375
A12: Damian Debek | B12: 233 | C12: =7.5*1.15 -> 8.625 | D12: 0.5 | E12: 0.5 | G12: 95 | H12: =(H$2-H$3)*$C12 -> 172.5 | I12: =(I$2-I$3)*$C12 -> 189.75 | J12: =(J$2-J$3)*$C12 -> 146.625 | K12: =(K$2-K$3)*$C12 -> 163.875 | L12: =(L$2-L$3)*$C12 -> 163.875 | M12: =(M$2-M$3)*$C12 -> 86.25 | N12: =(N$2-N$3)*$C12 -> 138 | O12: =(O$2-O$3)*$C12 -> 189.75 | ... R12: =(R$2-R$3)*$C12 -> 163.875 | S12: =SUM(G12:R12) -> 1880.375
A13: Andreas Jönsson | B13: 248 | C13: 7.5 | E13: 1 | G13: =(G$2-G$3)*$C13 -> 165 | H13: =(H$2-H$3)*$C13 -> 150 | I13: =(I$2-I$3)*$C13 -> 165 | J13: =(J$2-J$3)*$C13 -> 127.5 | K13: =(K$2-K$3)*$C13 -> 142.5 | L13: =(L$2-L$3)*$C13 -> 142.5 | M13: =(M$2-M$3)*$C13 -> 75 | N13: =(N$2-N$3)*$C13 -> 120 | ... R13: =(R$2-R$3)*$C13 -> 142.5 | S13: =SUM(G13:R13) -> 1717.5
A14: Lars Børge Olsen | B14: 248 | C14: 7.5 | E14: 1 | G14: =(G$2-G$3)*$C14 -> 165 | H14: =(H$2-H$3)*$C14 -> 150 | I14: =(I$2-I$3)*$C14 -> 165 | J14: =(J$2-J$3)*$C14 -> 127.5 | K14: =(K$2-K$3)*$C14 -> 142.5 | L14: =(L$2-L$3)*$C14 -> 142.5 | M14: =(M$2-M$3)*$C14 -> 75 | N14: =(N$2-N$3)*$C14 -> 120 | ... R14: =(R$2-R$3)*$C14 -> 142.5 | S14: =SUM(G14:R14) -> 1717.5
A15: Darius Fulgeanu | B15: 248 | C15: 7.5 | E15: 1 | G15: =(G$2-G$3)*$C15 -> 165 | H15: =(H$2-H$3)*$C15 -> 150 | I15: =(I$2-I$3)*$C15 -> 165 | J15: =(J$2-J$3)*$C15 -> 127.5 | K15: =(K$2-K$3)*$C15 -> 142.5 | L15: =(L$2-L$3)*$C15 -> 142.5 | M15: =(M$2-M$3)*$C15 -> 75 | N15: =(N$2-N$3)*$C15 -> 120 | ... R15: =(R$2-R$3)*$C15 -> 142.5 | S15: =SUM(G15:R15) -> 1717.5
A18: Christoffer Tønnesen Emilsen | B18: 190 | C18: 7.5 | D18: 1 | G18: =(G$2-G$3)*$C18 -> 165 | H18: =(H$2-H$3)*$C18 -> 150 | I18: =(I$2-I$3)*$C18 -> 165 | J18: =(J$2-J$3)*$C18 -> 127.5 | K18: =(K$2-K$3)*$C18 -> 142.5 | L18: =(L$2-L$3)*$C18 -> 142.5 | M18: =(M$2-M$3)*$C18 -> 75 | N18: =(N$2-N$3)*$C18 -> 120 | ... R18: =(R$2-R$3)*$C18 -> 142.5 | S18: =SUM(G18:R18) -> 1717.5
A19: Tommy Willumsen | B19: 248 | C19: 7.5 | D19: 1 | G19: =(G$2-G$3)*$C19 -> 165 | H19: =(H$2-H$3)*$C19 -> 150 | I19: =(I$2-I$3)*$C19 -> 165 | J19: =(J$2-J$3)*$C19 -> 127.5 | K19: =(K$2-K$3)*$C19 -> 142.5 | L19: =(L$2-L$3)*$C19 -> 142.5 | M19: =(M$2-M$3)*$C19 -> 75 | N19: =(N$2-N$3)*$C19 -> 120 | ... R19: =(R$2-R$3)*$C19 -> 142.5 | S19: =SUM(G19:R19) -> 1717.5
A20: Egidius Tumynas | B20: 248 | C20: 7.5 | D20: 1 | G20: =(G$2-G$3)*$C20 -> 165 | H20: =(H$2-H$3)*$C20 -> 150 | I20: =(I$2-I$3)*$C20 -> 165 | J20: =(J$2-J$3)*$C20 -> 127.5 | K20: =(K$2-K$3)*$C20 -> 142.5 | L20: =(L$2-L$3)*$C20 -> 142.5 | M20: =(M$2-M$3)*$C20 -> 75 | N20: =(N$2-N$3)*$C20 -> 120 | ... R20: =(R$2-R$3)*$C20 -> 142.5 | S20: =SUM(G20:R20) -> 1717.5
A21: Alf-Magne Nikolaisen | B21: 248 | C21: 7.5 | D21: 1 | G21: =(G$2-G$3)*$C21 -> 165 | H21: =(H$2-H$3)*$C21 -> 150 | I21: =(I$2-I$3)*$C21 -> 165 | J21: =(J$2-J$3)*$C21 -> 127.5 | K21: =(K$2-K$3)*$C21 -> 142.5 | L21: =(L$2-L$3)*$C21 -> 142.5 | M21: =(M$2-M$3)*$C21 -> 75 | N21: =(N$2-N$3)*$C21 -> 120 | ... R21: =(R$2-R$3)*$C21 -> 142.5 | S21: =SUM(G21:R21) -> 1717.5
A22: Richard Flage | B22: 248 | C22: 7.5 | D22: 1 | G22: =(G$2-G$3)*$C22 -> 165 | H22: =(H$2-H$3)*$C22 -> 150 | I22: =(I$2-I$3)*$C22 -> 165 | J22: =(J$2-J$3)*$C22 -> 127.5 | K22: =(K$2-K$3)*$C22 -> 142.5 | L22: =(L$2-L$3)*$C22 -> 142.5 | M22: =(M$2-M$3)*$C22 -> 75 | N22: =(N$2-N$3)*$C22 -> 120 | ... R22: =(R$2-R$3)*$C22 -> 142.5 | S22: =SUM(G22:R22) -> 1717.5
A23: Andre Skoglund | B23: 248 | C23: 7.5 | D23: 1 | G23: =(G$2-G$3)*$C23 -> 165 | H23: =(H$2-H$3)*$C23 -> 150 | I23: =(I$2-I$3)*$C23 -> 165 | J23: =(J$2-J$3)*$C23 -> 127.5 | K23: =(K$2-K$3)*$C23 -> 142.5 | L23: =(L$2-L$3)*$C23 -> 142.5 | M23: =(M$2-M$3)*$C23 -> 75 | N23: =(N$2-N$3)*$C23 -> 120 | ... R23: =(R$2-R$3)*$C23 -> 142.5 | S23: =SUM(G23:R23) -> 1717.5
A24: Tommy Johnsen | B24: 248 | C24: 7.5 | D24: 1 | G24: =(G$2-G$3)*$C24 -> 165 | H24: =(H$2-H$3)*$C24 -> 150 | I24: =(I$2-I$3)*$C24 -> 165 | J24: =(J$2-J$3)*$C24 -> 127.5 | K24: =(K$2-K$3)*$C24 -> 142.5 | L24: =(L$2-L$3)*$C24 -> 142.5 | M24: =(M$2-M$3)*$C24 -> 75 | N24: =(N$2-N$3)*$C24 -> 120 | ... R24: =(R$2-R$3)*$C24 -> 142.5 | S24: =SUM(G24:R24) -> 1717.5
A25: Christoffer Kamfjord Larsen | B25: 244 | C25: 7.5 | D25: 1 | G25: =(G$2-G$3)*$C25 -> 165 | H25: =(H$2-H$3)*$C25 -> 150 | I25: =(I$2-I$3)*$C25 -> 165 | J25: =(J$2-J$3)*$C25 -> 127.5 | K25: =(K$2-K$3)*$C25 -> 142.5 | L25: =(L$2-L$3)*$C25 -> 142.5 | M25: =(M$2-M$3)*$C25 -> 75 | N25: =(N$2-N$3)*$C25 -> 120 | ... R25: =(R$2-R$3)*$C25 -> 142.5 | S25: =SUM(G25:R25) -> 1717.5
A26: Eyas Mahmoud Salaman | B26: 225 | C26: 7.5 | D26: 1 | G26: =(G$2-G$3)*$C26 -> 165 | H26: =(H$2-H$3)*$C26 -> 150 | I26: =(I$2-I$3)*$C26 -> 165 | J26: =(J$2-J$3)*$C26 -> 127.5 | K26: =(K$2-K$3)*$C26 -> 142.5 | L26: =(L$2-L$3)*$C26 -> 142.5 | M26: =(M$2-M$3)*$C26 -> 75 | N26: =(N$2-N$3)*$C26 -> 120 | ... R26: =(R$2-R$3)*$C26 -> 142.5 | S26: =SUM(G26:R26) -> 1717.5
A27: Martin Olsen | B27: 233 | C27: 7.5 | D27: 1 | G27: =(G$2-G$3)*$C27 -> 165 | H27: =(H$2-H$3)*$C27 -> 150 | I27: =(I$2-I$3)*$C27 -> 165 | J27: =(J$2-J$3)*$C27 -> 127.5 | K27: =(K$2-K$3)*$C27 -> 142.5 | L27: =(L$2-L$3)*$C27 -> 142.5 | M27: =(M$2-M$3)*$C27 -> 75 | N27: =(N$2-N$3)*$C27 -> 120 | ... R27: =(R$2-R$3)*$C27 -> 142.5 | S27: =SUM(G27:R27) -> 1717.5
A28: Masod | B28: 248 | C28: 7.5 | D28: 1 | G28: =(G$2-G$3)*$C28 -> 165 | H28: =(H$2-H$3)*$C28 -> 150 | I28: =(I$2-I$3)*$C28 -> 165 | J28: =(J$2-J$3)*$C28 -> 127.5 | K28: =(K$2-K$3)*$C28 -> 142.5 | L28: =(L$2-L$3)*$C28 -> 142.5 | M28: =(M$2-M$3)*$C28 -> 75 | N28: =(N$2-N$3)*$C28 -> 120 | ... R28: =(R$2-R$3)*$C28 -> 142.5 | S28: =SUM(G28:R28) -> 1717.5
A29: Reza | B29: 248 | C29: 7.5 | D29: 1 | G29: =(G$2-G$3)*$C29 -> 165 | H29: =(H$2-H$3)*$C29 -> 150 | I29: =(I$2-I$3)*$C29 -> 165 | J29: =(J$2-J$3)*$C29 -> 127.5 | K29: =(K$2-K$3)*$C29 -> 142.5 | L29: =(L$2-L$3)*$C29 -> 142.5 | M29: =(M$2-M$3)*$C29 -> 75 | N29: =(N$2-N$3)*$C29 -> 120 | ... R29: =(R$2-R$3)*$C29 -> 142.5 | S29: =SUM(G29:R29) -> 1717.5
A30: Kidane | B30: 185 | C30: 7.5 | D30: 1 | G30: =(G$2-G$3)*$C30 -> 165 | H30: =(H$2-H$3)*$C30 -> 150 | I30: =(I$2-I$3)*$C30 -> 165 | J30: =(J$2-J$3)*$C30 -> 127.5 | K30: =(K$2-K$3)*$C30 -> 142.5 | L30: =(L$2-L$3)*$C30 -> 142.5 | M30: =(M$2-M$3)*$C30 -> 75 | N30: =(N$2-N$3)*$C30 -> 120 | ... R30: =(R$2-R$3)*$C30 -> 142.5 | S30: =SUM(G30:R30) -> 1717.5
A31: Viktor Jamtli | B31: 200 | C31: 7.5 | D31: 1 | H31: =(H$2-H$3)*$C31 -> 150 | I31: =(I$2-I$3)*$C31 -> 165 | J31: =(J$2-J$3)*$C31 -> 127.5 | K31: =(K$2-K$3)*$C31 -> 142.5 | L31: =(L$2-L$3)*$C31 -> 142.5 | M31: =(M$2-M$3)*$C31 -> 75 | N31: =(N$2-N$3)*$C31 -> 120 | S31: =SUM(G31:R31) -> 922.5
A32: Sesongarbeider utemaling | B32: 190 | C32: 7.5 | D32: 1 | K32: =(K$2-K$3)*$C32 -> 142.5 | L32: =(L$2-L$3)*$C32 -> 142.5 | M32: =(M$2-M$3)*$C32 -> 75 | N32: =(N$2-N$3)*$C32 -> 120 | O32: =(O$2-O$3)*$C32 -> 165 | S32: =SUM(G32:R32) -> 645
A33: Sesongarbeider utemaling | B33: 190 | C33: 7.5 | D33: 1 | K33: =(K$2-K$3)*$C33 -> 142.5 | L33: =(L$2-L$3)*$C33 -> 142.5 | M33: =(M$2-M$3)*$C33 -> 75 | N33: =(N$2-N$3)*$C33 -> 120 | O33: =(O$2-O$3)*$C33 -> 165 | S33: =SUM(G33:R33) -> 645
A34: Sesongarbeider utemaling | B34: 190 | C34: 7.5 | D34: 1 | K34: =(K$2-K$3)*$C34 -> 142.5 | L34: =(L$2-L$3)*$C34 -> 142.5 | M34: =(M$2-M$3)*$C34 -> 75 | N34: =(N$2-N$3)*$C34 -> 120 | O34: =(O$2-O$3)*$C34 -> 165 | S34: =SUM(G34:R34) -> 645
A37: Sum ordinære timer | G37: =SUM(G5:G35) -> 3625 | H37: =SUM(H5:H35) -> 3840 | I37: =SUM(I5:I35) -> 4224 | J37: =SUM(J5:J35) -> 3264 | K37: =SUM(K5:K35) -> 4075.5 | L37: =SUM(L5:L35) -> 4075.5 | M37: =SUM(M5:M35) -> 2145 | N37: =SUM(N5:N35) -> 3432 | ... S37: =SUM(S5:S35) -> 44674
